<?xml version="1.0" ?>
<!--
  Gazebo Ackermann steering plugin demo

STEERING
gz topic -t "/gz/delta_l" -m gz.msgs.Double -p "data: -0.3"
gz topic -t "/delta_r" -m gz.msgs.Double -p "data: -0.3"

MOVING WHEELS
gz topic -t "/wheel_speed" -m gz.msgs.Double -p "data: 1.0"

-->
<sdf version="1.6">
  <!-- <world name="pruebas">
    <model name="ground_plane">
      <static>true</static>
      <link name="link">
        <collision name="collision">
          <geometry>
            <plane>
              <normal>0 0 1</normal>
              <size>100 100</size>
            </plane>
          </geometry>
          <surface>
            <friction>
              <ode>
                <mu>50</mu>
              </ode>
              <bullet>
                <friction>1</friction>
                <rolling_friction>0.1</rolling_friction>
              </bullet>
            </friction>
          </surface>
        </collision>
        <visual name="visual">
          <geometry>
            <plane>
              <normal>0 0 1</normal>
              <size>100 100</size>
            </plane>
          </geometry>
          <material>
            <ambient>0.8 0.8 0.8 1</ambient>
            <diffuse>0.8 0.8 0.8 1</diffuse>
            <specular>0.8 0.8 0.8 1</specular>
          </material>
        </visual>
      </link>
    </model> -->


  <model name='vtec_delorean'>
    <pose>0 2 0.325 0 -0 0</pose>

    <link name='chassis'>
      <pose>0 0 0.6 0 0 -1.5708</pose>
      <inertial>
        <mass>1.14395</mass>
        <inertia>
          <ixx>0.126164</ixx>
          <ixy>0</ixy>
          <ixz>0</ixz>
          <iyy>0.416519</iyy>
          <iyz>0</iyz>
          <izz>0.481014</izz>
        </inertia>
      </inertial>
      <visual name='visual'>

        <geometry>
          <mesh>
            <uri>file://vtec_sdv/meshes/sdv_chassis.dae</uri>
            <scale>1 1 1</scale>
          </mesh>
        </geometry>
        
        <material>
          <ambient>0.9 0.9 1.0 1</ambient>
          <diffuse>0.9 0.9 1.0 1</diffuse>
          <specular>0.9 0.9 1.0 1</specular>
        </material>
      </visual>
      <!-- <collision name='collision0'>
        <pose>0 0 0.1 0.0 0.0 0.0</pose>
        <geometry>
          <box>
            <size>1.5 4 0.6</size>
          </box>
        </geometry>
      </collision>
      <collision name='collision1'>
        <pose>0 1.85 0 0.0 0.0 0.0</pose>
        <geometry>
          <box>
            <size>1.7 0.5 1.6</size>
          </box>
        </geometry>
      </collision>
      <collision name='collision2'>
        <pose>0 -1.92 0 0.0 0.0 0.0</pose>
        <geometry>
          <box>
            <size>1.5 0.5 1.6</size>
          </box>
        </geometry>
      </collision> -->
      <collision name='collision_car_shaped'>
        <geometry>
          <mesh>
            <uri>file://vtec_sdv/meshes/sdv_chassis.dae</uri>
            <scale>1 1 1</scale>
          </mesh>
        </geometry>
      </collision>

      <sensor name='gpu_lidar' type='gpu_lidar'>
        <pose>0 2 1 0 0 0</pose>
        <topic>lidar</topic>
        <update_rate>10</update_rate>
        <lidar>
          <scan>
            <horizontal>
              <samples>640</samples>
              <resolution>1</resolution>
              <min_angle>-3.14</min_angle>
              <max_angle>3.14</max_angle>
            </horizontal>
            <vertical>
              <samples>16</samples>
              <resolution>1</resolution>
              <min_angle>-1</min_angle>
              <max_angle>1</max_angle>
            </vertical>
          </scan>
          <range>
            <min>0.2</min>
            <max>20.0</max>
            <resolution>0.01</resolution>
          </range>
        </lidar>
        <alwaysOn>1</alwaysOn>
        <visualize>true</visualize>
        <plugin
          filename="RosGzPointCloud"
          name="ros_gz_point_cloud::PointCloud">
          <namespace>custom_params</namespace>
          <topic>pc2</topic>
          <frame_id>custom_params/link</frame_id>
        </plugin>
      </sensor>

      <sensor name="rgbd_camera" type="rgbd_camera">
        <pose>0 2.3 0 0 0 1.57078</pose>
        <camera>
          <horizontal_fov>1.047</horizontal_fov>
          <image>
            <width>320</width>
            <height>240</height>
          </image>
          <clip>
            <near>0.1</near>
            <far>100</far>
          </clip>
        </camera>
        <always_on>1</always_on>
        <update_rate>30</update_rate>
        <visualize>true</visualize>
        <topic>zed_rgbd</topic>
        <plugin
          filename="RosGzPointCloud"
          name="ros_gz_point_cloud::PointCloud">
          <namespace>custom_params</namespace>
          <topic>pc2</topic>
          <frame_id>map</frame_id>
        </plugin>
      </sensor>
    </link>

    <link name='front_left_wheel'>
      <pose>0.954283 0.625029 -0.025 -1.5707 0 0</pose>
      <inertial>
        <mass>2</mass>
        <inertia>
          <ixx>0.145833</ixx>
          <ixy>0</ixy>
          <ixz>0</ixz>
          <iyy>0.145833</iyy>
          <iyz>0</iyz>
          <izz>0.125</izz>
        </inertia>
      </inertial>
      <visual name='visual'>

        <pose>0 0 0.1 0 1.5708 0</pose>
        <geometry>
          <mesh>
            <uri>file://vtec_sdv/meshes/sdv_wheel.dae</uri>
            <scale>0.1 0.1 0.1</scale>
          </mesh>
        </geometry>

        <material>
          <ambient>0.2 0.2 0.2 1</ambient>
          <diffuse>0.2 0.2 0.2 1</diffuse>
          <specular>0.2 0.2 0.2 1</specular>
        </material>
      </visual>
      <collision name='collision'>
        <geometry>
          <cylinder>
            <length>0.15</length>
            <radius>0.3</radius>
          </cylinder>
        </geometry>
        <surface>
          <friction>
            <ode>
              <mu>0.5</mu>
              <mu2>1.0</mu2>
              <fdir1>0 0 1</fdir1>
            </ode>
            <bullet>
              <friction>0.5</friction>
              <friction2>1</friction2>
              <rolling_friction>0.1</rolling_friction>
            </bullet>
          </friction>
        </surface>
      </collision>
    </link>

    <link name='rear_left_wheel'>
      <pose>-1.157138 0.625029 -0.025 -1.5707 0 0</pose>
      <inertial>
        <mass>2</mass>
        <inertia>
          <ixx>0.145833</ixx>
          <ixy>0</ixy>
          <ixz>0</ixz>
          <iyy>0.145833</iyy>
          <iyz>0</iyz>
          <izz>0.125</izz>
        </inertia>
      </inertial>
      <visual name='visual'>
        <pose>0 0 0.1 0 1.5708 0</pose>
        <geometry>
          <mesh>
            <uri>file://vtec_sdv/meshes/sdv_wheel.dae</uri>
            <scale>0.1 0.1 0.1</scale>
          </mesh>
        </geometry>
        <material>
          <ambient>0.2 0.2 0.2 1</ambient>
          <diffuse>0.2 0.2 0.2 1</diffuse>
          <specular>0.2 0.2 0.2 1</specular>
        </material>
      </visual>
      <collision name='collision'>
        <geometry>
          <cylinder>
            <length>0.15</length>
            <radius>0.3</radius>
          </cylinder>
        </geometry>
        <surface>
          <friction>
            <ode>
              <mu>0.5</mu>
              <mu2>1.0</mu2>
              <fdir1>0 0 1</fdir1>
            </ode>
            <bullet>
              <friction>0.5</friction>
              <friction2>1</friction2>
              <rolling_friction>0.5</rolling_friction>
            </bullet>
          </friction>
        </surface>
      </collision>
    </link>

    <link name='front_right_wheel'>
      <pose>0.954282 -0.625029 -0.025 -1.5707 0 0</pose>
      <inertial>
        <mass>2</mass>
        <inertia>
          <ixx>0.145833</ixx>
          <ixy>0</ixy>
          <ixz>0</ixz>
          <iyy>0.145833</iyy>
          <iyz>0</iyz>
          <izz>0.125</izz>
        </inertia>
      </inertial>
      <visual name='visual'>
        <pose>0 0 -0.1 0 -1.5708 0</pose>
        <geometry>
          <mesh>
            <uri>file://vtec_sdv/meshes/sdv_wheel.dae</uri>
            <scale>0.1 0.1 0.1</scale>
          </mesh>
        </geometry>
        <material>
          <ambient>0.2 0.2 0.2 1</ambient>
          <diffuse>0.2 0.2 0.2 1</diffuse>
          <specular>0.2 0.2 0.2 1</specular>
        </material>
      </visual>
      <collision name='collision'>
        <geometry>
          <cylinder>
            <length>0.15</length>
            <radius>0.3</radius>
          </cylinder>
        </geometry>
        <surface>
          <friction>
            <ode>
              <mu>0.5</mu>
              <mu2>1.0</mu2>
              <fdir1>0 0 1</fdir1>
            </ode>
            <bullet>
              <friction>0.5</friction>
              <friction2>1</friction2>
              <rolling_friction>0.1</rolling_friction>
            </bullet>
          </friction>
        </surface>
      </collision>
    </link>

    <link name='rear_right_wheel'>
      <pose>-1.157138 -0.625029 -0.025 -1.5707 0 0</pose>
      <inertial>
        <mass>2</mass>
        <inertia>
          <ixx>0.145833</ixx>
          <ixy>0</ixy>
          <ixz>0</ixz>
          <iyy>0.145833</iyy>
          <iyz>0</iyz>
          <izz>0.125</izz>
        </inertia>
      </inertial>
      <visual name='visual'>
        <pose>0 0 -0.1 0 -1.5708 0</pose>
        <geometry>
          <mesh>
            <uri>file://vtec_sdv/meshes/sdv_wheel.dae</uri>
            <scale>0.1 0.1 0.1</scale>
          </mesh>
        </geometry>
        <material>
          <ambient>0.2 0.2 0.2 1</ambient>
          <diffuse>0.2 0.2 0.2 1</diffuse>
          <specular>0.2 0.2 0.2 1</specular>
        </material>
      </visual>
      <collision name='collision'>
        <geometry>
          <cylinder>
            <length>0.15</length>
            <radius>0.3</radius>
          </cylinder>
        </geometry>
        <surface>
          <friction>
            <ode>
              <mu>0.5</mu>
              <mu2>1.0</mu2>
              <fdir1>0 0 1</fdir1>
            </ode>
            <bullet>
              <friction>0.5</friction>
              <friction2>1</friction2>
              <rolling_friction>0.5</rolling_friction>
            </bullet>
          </friction>
        </surface>
      </collision>
    </link>

    <link name="front_left_wheel_steering_link">
      <pose>0.954283 0.5 0.02 0 0 0</pose>
      <inertial>
        <mass>0.5</mass>
        <inertia>
          <ixx>0.0153</ixx>
          <iyy>0.025</iyy>
          <izz>0.0153</izz>
        </inertia>
      </inertial>
      <visual name="steering_link_visual">
        <pose>0 0 0 0 0 0</pose>
        <geometry>
          <cylinder>
            <length>0.1</length>
            <radius>0.03</radius>
          </cylinder>
        </geometry>
        <material>
          <ambient>1 1 1</ambient>
          <diffuse>1 1 1</diffuse>
        </material>
      </visual>
    </link>

    <link name="front_right_wheel_steering_link">
      <pose>0.954283 -0.5 0.02 0 0 0</pose>
      <inertial>
        <mass>0.5</mass>
        <inertia>
          <ixx>0.0153</ixx>
          <iyy>0.025</iyy>
          <izz>0.0153</izz>
        </inertia>
      </inertial>
      <visual name="steering_link_visual">
        <pose>0 0 0 0 0 0</pose>
        <geometry>
          <cylinder>
            <length>0.1</length>
            <radius>0.03</radius>
          </cylinder>
        </geometry>
        <material>
          <ambient>1 1 1</ambient>
          <diffuse>1 1 1</diffuse>
        </material>
      </visual>
    </link>

    <joint name="front_left_wheel_steering_joint" type="revolute">
      <child>front_left_wheel_steering_link</child>
      <parent>chassis</parent>
      <axis>
        <xyz>0 0 1</xyz>
        <limit>
          <lower>-0.6</lower>
          <upper>+0.6</upper>
          <velocity>1.0</velocity>
          <effort>25</effort>
        </limit>
        <use_parent_model_frame>1</use_parent_model_frame>
      </axis>
    </joint>

    <joint name="front_right_wheel_steering_joint" type="revolute">
      <parent>chassis</parent>
      <child>front_right_wheel_steering_link</child>
      <axis>
        <xyz>0 0 1</xyz>
        <limit>
          <lower>-0.6</lower>
          <upper>+0.6</upper>
          <velocity>1.0</velocity>
          <effort>25</effort>
        </limit>
      </axis>
    </joint>

    <joint name='front_left_wheel_joint' type='revolute'>
      <parent>front_left_wheel_steering_link</parent>
      <child>front_left_wheel</child>
      <axis>
        <xyz>0 0 1</xyz>
        <limit>
          <lower>-1.79769e+308</lower>
          <upper>1.79769e+308</upper>
        </limit>
      </axis>
    </joint>

    <joint name='front_right_wheel_joint' type='revolute'>
      <parent>front_right_wheel_steering_link</parent>
      <child>front_right_wheel</child>
      <axis>
        <xyz>0 0 1</xyz>
        <limit>
          <lower>-1.79769e+308</lower>
          <upper>1.79769e+308</upper>
        </limit>
      </axis>
    </joint>

    <joint name='rear_left_wheel_joint' type='revolute'>
      <parent>chassis</parent>
      <child>rear_left_wheel</child>
      <axis>
        <xyz>0 0 1</xyz>
        <limit>
          <lower>-1.79769e+308</lower>
          <upper>1.79769e+308</upper>
        </limit>
      </axis>
    </joint>

    <joint name='rear_right_wheel_joint' type='revolute'>
      <parent>chassis</parent>
      <child>rear_right_wheel</child>
      <axis>
        <xyz>0 0 1</xyz>
        <limit>
          <lower>-1.79769e+308</lower>
          <upper>1.79769e+308</upper>
        </limit>
      </axis>
    </joint>

    <plugin
      filename="gz-sim-joint-position-controller-system"
      name="gz::sim::systems::JointPositionController">
      <joint_name>front_left_wheel_steering_joint</joint_name>
      <topic>delta_l</topic>
      <p_gain>10</p_gain>
      <i_gain>1</i_gain>
      <d_gain>2</d_gain>
      <i_max>1</i_max>
      <i_min>-1</i_min>
      <cmd_max>30</cmd_max>
      <cmd_min>-30</cmd_min>
    </plugin>
    <plugin
      filename="gz-sim-joint-position-controller-system"
      name="gz::sim::systems::JointPositionController">
      <joint_name>front_right_wheel_steering_joint</joint_name>
      <topic>delta_r</topic>
      <p_gain>10</p_gain>
      <i_gain>1</i_gain>
      <d_gain>2</d_gain>
      <i_max>1</i_max>
      <i_min>-1</i_min>
      <cmd_max>30</cmd_max>
      <cmd_min>-30</cmd_min>
    </plugin>

    <plugin
      filename="gz-sim-joint-controller-system"
      name="gz::sim::systems::JointController">
      <joint_name>front_left_wheel_joint</joint_name>
      <initial_velocity>0.0</initial_velocity>
      <topic>wheel_speed</topic>
    </plugin>
    <plugin
      filename="gz-sim-joint-controller-system"
      name="gz::sim::systems::JointController">
      <joint_name>rear_left_wheel_joint</joint_name>
      <initial_velocity>0.0</initial_velocity>
      <topic>wheel_speed</topic>
    </plugin>
    <plugin
      filename="gz-sim-joint-controller-system"
      name="gz::sim::systems::JointController">
      <joint_name>front_right_wheel_joint</joint_name>
      <initial_velocity>0.0</initial_velocity>
      <topic>wheel_speed</topic>
    </plugin>
    <plugin
      filename="gz-sim-joint-controller-system"
      name="gz::sim::systems::JointController">
      <joint_name>rear_right_wheel_joint</joint_name>
      <initial_velocity>0.0</initial_velocity>
      <topic>wheel_speed</topic>
    </plugin>

    <plugin
      filename="gz-sim-odometry-publisher-system"
      name="gz::sim::systems::OdometryPublisher">
      <odom_frame>world</odom_frame>
      <odom_covariance_topic>/gz_sim/odometry</odom_covariance_topic>
    </plugin>


    <!-- <plugin
      filename="gz-sim-ackermann-steering-system"
      name="gz::sim::systems::AckermannSteering">
      <left_joint>front_left_wheel_joint</left_joint>
      <left_joint>rear_left_wheel_joint</left_joint>
      <right_joint>front_right_wheel_joint</right_joint>
      <right_joint>rear_right_wheel_joint</right_joint>
      <left_steering_joint>front_left_wheel_steering_joint</left_steering_joint>
      <right_steering_joint>front_right_wheel_steering_joint</right_steering_joint>
      <kingpin_width>1.0</kingpin_width>
      <steering_limit>0.5</steering_limit>
      <wheel_base>1.0</wheel_base>
      <wheel_separation>1.25</wheel_separation>
      <wheel_radius>0.3</wheel_radius>
      <min_velocity>-1</min_velocity>
      <max_velocity>1</max_velocity>
      <min_acceleration>-3</min_acceleration>
      <max_acceleration>3</max_acceleration>
    </plugin> -->

    </model>


  <!-- </world> -->
</sdf>